{
    "WizardLM": {
      "zero-shot": {
        "status": "failed",
        "coverage": "-",
        "assert_types": [
          "assertRaises",
          "assertEqual"
        ],
        "edge_case_found": true,
        "functions_tested": 1,
        "total_functions": 2,
        "score": 0.37,
        "stdout": "Couldn't run 'C:\\Users\\antho\\OneDrive\\Área de Trabalho\\testPilotAI\\test_outputs\\WizardLM_zero-shot.py' as Python code: SyntaxError: closing parenthesis ')' does not match opening parenthesis '[' (WizardLM_zero-shot.py, line 12)\n",
        "stderr": "C:\\Users\\antho\\OneDrive\\Área de Trabalho\\testPilotAI\\venv\\Lib\\site-packages\\coverage\\control.py:915: CoverageWarning: No data was collected. (no-data-collected)\n  self._warn(\"No data was collected.\", slug=\"no-data-collected\")\n",
        "test_smells": {
          "syntax_error": 1
        }
      },
      "few-shot": {
        "status": "failed",
        "coverage": "-",
        "assert_types": [
          "assertRaises",
          "assertEqual"
        ],
        "edge_case_found": true,
        "functions_tested": 1,
        "total_functions": 2,
        "score": -0.03,
        "stdout": "",
        "stderr": "Traceback (most recent call last):\n  File \"C:\\Users\\antho\\OneDrive\\Área de Trabalho\\testPilotAI\\test_outputs\\WizardLM_few-shot.py\", line 4, in <module>\n    from max_chain_length import max_chain_length, Pair\nModuleNotFoundError: No module named 'max_chain_length'\n",
        "test_smells": {
          "redundant_assertion": 3,
          "magic_number": 62,
          "assertion_roulette": 2
        }
      },
      "cot": {
        "status": "failed",
        "coverage": "-",
        "assert_types": [
          "assertEqual"
        ],
        "edge_case_found": true,
        "functions_tested": 2,
        "total_functions": 2,
        "score": 0.35,
        "stdout": "",
        "stderr": "F..FFEFFEF.F\n======================================================================\nERROR: test_mixed_array (__main__.TestMaxChainLength.test_mixed_array)\n----------------------------------------------------------------------\nTraceback (most recent call last):\n  File \"C:\\Users\\antho\\OneDrive\\Área de Trabalho\\testPilotAI\\test_outputs\\WizardLM_cot.py\", line 50, in test_mixed_array\n    self.assertEqual(max_chain_length(arr, n), 1)\n                     ^^^^^^^^^^^^^^^^^^^^^^^^\n  File \"C:\\Users\\antho\\OneDrive\\Área de Trabalho\\testPilotAI\\prompts\\code.py\", line 19, in max_chain_length\n    if (arr[i].a > arr[j].b and\n        ^^^^^^^^^^^^^^^^^^^\nTypeError: '>' not supported between instances of 'str' and 'int'\n\n======================================================================\nERROR: test_non_comparable_elements (__main__.TestMaxChainLength.test_non_comparable_elements)\n----------------------------------------------------------------------\nTraceback (most recent call last):\n  File \"C:\\Users\\antho\\OneDrive\\Área de Trabalho\\testPilotAI\\test_outputs\\WizardLM_cot.py\", line 25, in test_non_comparable_elements\n    self.assertEqual(max_chain_length(arr, n), 1)\n                     ^^^^^^^^^^^^^^^^^^^^^^^^\n  File \"C:\\Users\\antho\\OneDrive\\Área de Trabalho\\testPilotAI\\prompts\\code.py\", line 19, in max_chain_length\n    if (arr[i].a > arr[j].b and\n        ^^^^^^^^^^^^^^^^^^^\nTypeError: '>' not supported between instances of 'int' and 'str'\n\n======================================================================\nFAIL: test_all_pairs_comparable (__main__.TestMaxChainLength.test_all_pairs_comparable)\n----------------------------------------------------------------------\nTraceback (most recent call last):\n  File \"C:\\Users\\antho\\OneDrive\\Área de Trabalho\\testPilotAI\\test_outputs\\WizardLM_cot.py\", line 30, in test_all_pairs_comparable\n    self.assertEqual(max_chain_length(arr, n), 2)\nAssertionError: 3 != 2\n\n======================================================================\nFAIL: test_large_input_with_duplicates (__main__.TestMaxChainLength.test_large_input_with_duplicates)\n----------------------------------------------------------------------\nTraceback (most recent call last):\n  File \"C:\\Users\\antho\\OneDrive\\Área de Trabalho\\testPilotAI\\test_outputs\\WizardLM_cot.py\", line 70, in test_large_input_with_duplicates\n    self.assertEqual(max_chain_length(arr, n), 1000)\nAssertionError: 1001 != 1000\n\n======================================================================\nFAIL: test_large_inputs (__main__.TestMaxChainLength.test_large_inputs)\n----------------------------------------------------------------------\nTraceback (most recent call last):\n  File \"C:\\Users\\antho\\OneDrive\\Área de Trabalho\\testPilotAI\\test_outputs\\WizardLM_cot.py\", line 60, in test_large_inputs\n    self.assertEqual(max_chain_length(arr, n), 999)\nAssertionError: 1 != 999\n\n======================================================================\nFAIL: test_multiple_chains (__main__.TestMaxChainLength.test_multiple_chains)\n----------------------------------------------------------------------\nTraceback (most recent call last):\n  File \"C:\\Users\\antho\\OneDrive\\Área de Trabalho\\testPilotAI\\test_outputs\\WizardLM_cot.py\", line 45, in test_multiple_chains\n    self.assertEqual(max_chain_length(arr, n), 3)\nAssertionError: 4 != 3\n\n======================================================================\nFAIL: test_no_chains_formed (__main__.TestMaxChainLength.test_no_chains_formed)\n----------------------------------------------------------------------\nTraceback (most recent call last):\n  File \"C:\\Users\\antho\\OneDrive\\Área de Trabalho\\testPilotAI\\test_outputs\\WizardLM_cot.py\", line 35, in test_no_chains_formed\n    self.assertEqual(max_chain_length(arr, n), 0)\nAssertionError: 1 != 0\n\n======================================================================\nFAIL: test_optimization (__main__.TestMaxChainLength.test_optimization)\n----------------------------------------------------------------------\nTraceback (most recent call last):\n  File \"C:\\Users\\antho\\OneDrive\\Área de Trabalho\\testPilotAI\\test_outputs\\WizardLM_cot.py\", line 65, in test_optimization\n    self.assertEqual(max_chain_length(arr, n), 2)\nAssertionError: 3 != 2\n\n======================================================================\nFAIL: test_trivial_chains (__main__.TestMaxChainLength.test_trivial_chains)\n----------------------------------------------------------------------\nTraceback (most recent call last):\n  File \"C:\\Users\\antho\\OneDrive\\Área de Trabalho\\testPilotAI\\test_outputs\\WizardLM_cot.py\", line 40, in test_trivial_chains\n    self.assertEqual(max_chain_length(arr, n), 4)\nAssertionError: 3 != 4\n\n----------------------------------------------------------------------\nRan 12 tests in 0.234s\n\nFAILED (failures=7, errors=2)\n",
        "test_smells": {
          "redundant_assertion": 6,
          "magic_number": 50
        }
      }
    },
    "CodeLLaMA": {
      "zero-shot": {
        "status": "passed",
        "coverage": "11%",
        "assert_types": [
          "assertEqual"
        ],
        "edge_case_found": true,
        "functions_tested": 1,
        "total_functions": 2,
        "score": 2.35,
        "stdout": "",
        "stderr": "",
        "test_smells": {
          "redundant_assertion": 3,
          "magic_number": 12
        }
      },
      "few-shot": {
        "status": "no_code_found",
        "score": 0.0
      },
      "cot": {
        "status": "passed",
        "coverage": "11%",
        "assert_types": [
          "assertEqual"
        ],
        "edge_case_found": true,
        "functions_tested": 1,
        "total_functions": 2,
        "score": 2.35,
        "stdout": "",
        "stderr": "",
        "test_smells": {
          "redundant_assertion": 2,
          "magic_number": 13
        }
      }
    },
    "WizardCoder": {
      "zero-shot": {
        "status": "failed",
        "coverage": "-",
        "assert_types": [
          "assertEqual"
        ],
        "edge_case_found": true,
        "functions_tested": 2,
        "total_functions": 2,
        "score": 0.55,
        "stdout": "",
        "stderr": "F\n======================================================================\nFAIL: test_max_chain_length (__main__.TestPair.test_max_chain_length)\n----------------------------------------------------------------------\nTraceback (most recent call last):\n  File \"C:\\Users\\antho\\OneDrive\\Área de Trabalho\\testPilotAI\\test_outputs\\WizardCoder_zero-shot.py\", line 17, in test_max_chain_length\n    self.assertEqual(result, 2)\nAssertionError: 4 != 2\n\n----------------------------------------------------------------------\nRan 1 test in 0.001s\n\nFAILED (failures=1)\n",
        "test_smells": {
          "magic_number": 8
        }
      },
      "few-shot": {
        "status": "failed",
        "coverage": "-",
        "assert_types": [
          "assertEqual"
        ],
        "edge_case_found": true,
        "functions_tested": 1,
        "total_functions": 2,
        "score": 0.1,
        "stdout": "",
        "stderr": ".F.FF\n======================================================================\nFAIL: test_case2 (__main__.TestMaxChainLength.test_case2)\n----------------------------------------------------------------------\nTraceback (most recent call last):\n  File \"C:\\Users\\antho\\OneDrive\\Área de Trabalho\\testPilotAI\\test_outputs\\WizardCoder_few-shot.py\", line 14, in test_case2\n    self.assertEqual(max_chain_length(arr, n), 1) # expected output: 1 (since there is only one chain of length 2, [10, 6])\n    ^^^^^^^^^^^^^^^^^^^^^^^^^^^^^^^^^^^^^^^^^^^^^\nAssertionError: 3 != 1\n\n======================================================================\nFAIL: test_case4 (__main__.TestMaxChainLength.test_case4)\n----------------------------------------------------------------------\nTraceback (most recent call last):\n  File \"C:\\Users\\antho\\OneDrive\\Área de Trabalho\\testPilotAI\\test_outputs\\WizardCoder_few-shot.py\", line 24, in test_case4\n    self.assertEqual(max_chain_length(arr, n), 0) # expected output: 0 (since there is only one chain of length 1 [1, 2], [3, 4] and [5, 6])\n    ^^^^^^^^^^^^^^^^^^^^^^^^^^^^^^^^^^^^^^^^^^^^^\nAssertionError: 3 != 0\n\n======================================================================\nFAIL: test_case5 (__main__.TestMaxChainLength.test_case5)\n----------------------------------------------------------------------\nTraceback (most recent call last):\n  File \"C:\\Users\\antho\\OneDrive\\Área de Trabalho\\testPilotAI\\test_outputs\\WizardCoder_few-shot.py\", line 29, in test_case5\n    self.assertEqual(max_chain_length(arr, n), 0) # expected output: 0 (since there is only one chain of length 1 [-1, -2] and [7, 8])\n    ^^^^^^^^^^^^^^^^^^^^^^^^^^^^^^^^^^^^^^^^^^^^^\nAssertionError: 2 != 0\n\n----------------------------------------------------------------------\nRan 5 tests in 0.002s\n\nFAILED (failures=3)\n",
        "test_smells": {
          "redundant_assertion": 4,
          "magic_number": 22
        }
      },
      "cot": {
        "status": "no_code_found",
        "score": 0.0
      }
    },
    "LLaMA3": {
      "zero-shot": {
        "status": "failed",
        "coverage": "-",
        "assert_types": [
          "assertEqual"
        ],
        "edge_case_found": true,
        "functions_tested": 1,
        "total_functions": 2,
        "score": 0.1,
        "stdout": "",
        "stderr": "Traceback (most recent call last):\n  File \"C:\\Users\\antho\\OneDrive\\Área de Trabalho\\testPilotAI\\test_outputs\\LLaMA3_zero-shot.py\", line 4, in <module>\n    from your_module import Pair, max_chain_length  # replace 'your_module' with the actual name of the module where the function is defined\n    ^^^^^^^^^^^^^^^^^^^^^^^^^^^^^^^^^^^^^^^^^^^^^^\nModuleNotFoundError: No module named 'your_module'\n",
        "test_smells": {
          "redundant_assertion": 2,
          "magic_number": 14
        }
      },
      "few-shot": {
        "status": "failed",
        "coverage": "-",
        "assert_types": [
          "assertRaises",
          "assertEqual"
        ],
        "edge_case_found": true,
        "functions_tested": 1,
        "total_functions": 2,
        "score": -0.03,
        "stdout": "",
        "stderr": "Traceback (most recent call last):\n  File \"C:\\Users\\antho\\OneDrive\\Área de Trabalho\\testPilotAI\\test_outputs\\LLaMA3_few-shot.py\", line 4, in <module>\n    from your_module import Pair, max_chain_length  # Import the Pair and max_chain_length functions\n    ^^^^^^^^^^^^^^^^^^^^^^^^^^^^^^^^^^^^^^^^^^^^^^\nModuleNotFoundError: No module named 'your_module'\n",
        "test_smells": {
          "redundant_assertion": 3,
          "magic_number": 33,
          "assertion_roulette": 2
        }
      },
      "cot": {
        "status": "failed",
        "coverage": "-",
        "assert_types": [
          "assertEqual",
          "assertLessEqual"
        ],
        "edge_case_found": true,
        "functions_tested": 1,
        "total_functions": 2,
        "score": 0.17,
        "stdout": "",
        "stderr": ".F.FF.\n======================================================================\nFAIL: test_multiple_chains (__main__.TestMaxChainLength.test_multiple_chains)\n----------------------------------------------------------------------\nTraceback (most recent call last):\n  File \"C:\\Users\\antho\\OneDrive\\Área de Trabalho\\testPilotAI\\test_outputs\\LLaMA3_cot.py\", line 21, in test_multiple_chains\n    self.assertEqual(max_chain_length(arr, n), 2)\nAssertionError: 1 != 2\n\n======================================================================\nFAIL: test_no_optimal_chain (__main__.TestMaxChainLength.test_no_optimal_chain)\n----------------------------------------------------------------------\nTraceback (most recent call last):\n  File \"C:\\Users\\antho\\OneDrive\\Área de Trabalho\\testPilotAI\\test_outputs\\LLaMA3_cot.py\", line 38, in test_no_optimal_chain\n    self.assertLessEqual(max_chain_length(arr, n), 1)\nAssertionError: 3 not less than or equal to 1\n\n======================================================================\nFAIL: test_optimal_chain (__main__.TestMaxChainLength.test_optimal_chain)\n----------------------------------------------------------------------\nTraceback (most recent call last):\n  File \"C:\\Users\\antho\\OneDrive\\Área de Trabalho\\testPilotAI\\test_outputs\\LLaMA3_cot.py\", line 32, in test_optimal_chain\n    self.assertEqual(max_chain_length(arr, n), 5)\nAssertionError: 3 != 5\n\n----------------------------------------------------------------------\nRan 6 tests in 0.002s\n\nFAILED (failures=3)\n",
        "test_smells": {
          "redundant_assertion": 3,
          "magic_number": 32
        }
      }
    },
    "Gemma": {
      "zero-shot": {
        "status": "failed",
        "coverage": "-",
        "assert_types": [
          "assertEqual"
        ],
        "edge_case_found": true,
        "functions_tested": 1,
        "total_functions": 2,
        "score": 0.1,
        "stdout": "",
        "stderr": "Traceback (most recent call last):\n  File \"C:\\Users\\antho\\OneDrive\\Área de Trabalho\\testPilotAI\\test_outputs\\Gemma_zero-shot.py\", line 5, in <module>\n    from chain_length import Pair, max_chain_length\nModuleNotFoundError: No module named 'chain_length'\n",
        "test_smells": {
          "redundant_assertion": 2,
          "magic_number": 14
        }
      },
      "few-shot": {
        "status": "failed",
        "coverage": "-",
        "assert_types": [
          "assertEqual"
        ],
        "edge_case_found": true,
        "functions_tested": 1,
        "total_functions": 2,
        "score": 0.1,
        "stdout": "",
        "stderr": "Traceback (most recent call last):\n  File \"C:\\Users\\antho\\OneDrive\\Área de Trabalho\\testPilotAI\\test_outputs\\Gemma_few-shot.py\", line 5, in <module>\n    from chain import Pair, max_chain_length\nModuleNotFoundError: No module named 'chain'\n",
        "test_smells": {
          "redundant_assertion": 2,
          "magic_number": 15
        }
      },
      "cot": {
        "status": "failed",
        "coverage": "-",
        "assert_types": [
          "assertEqual"
        ],
        "edge_case_found": true,
        "functions_tested": 1,
        "total_functions": 2,
        "score": 0.1,
        "stdout": "",
        "stderr": "Traceback (most recent call last):\n  File \"C:\\Users\\antho\\OneDrive\\Área de Trabalho\\testPilotAI\\test_outputs\\Gemma_cot.py\", line 5, in <module>\n    from chain import Pair, max_chain_length\nModuleNotFoundError: No module named 'chain'\n",
        "test_smells": {
          "magic_number": 20,
          "redundant_assertion": 2
        }
      }
    },
    "CodeGemma": {
      "zero-shot": {
        "status": "failed",
        "coverage": "-",
        "assert_types": [
          "assertEqual"
        ],
        "edge_case_found": true,
        "functions_tested": 1,
        "total_functions": 2,
        "score": 0.1,
        "stdout": "",
        "stderr": "..FF\n======================================================================\nFAIL: test_sorted_array (__main__.TestMaxChainLength.test_sorted_array)\n----------------------------------------------------------------------\nTraceback (most recent call last):\n  File \"C:\\Users\\antho\\OneDrive\\Área de Trabalho\\testPilotAI\\test_outputs\\CodeGemma_zero-shot.py\", line 16, in test_sorted_array\n    self.assertEqual(max_chain_length(pairs, 5), 5)\nAssertionError: 3 != 5\n\n======================================================================\nFAIL: test_unsorted_array (__main__.TestMaxChainLength.test_unsorted_array)\n----------------------------------------------------------------------\nTraceback (most recent call last):\n  File \"C:\\Users\\antho\\OneDrive\\Área de Trabalho\\testPilotAI\\test_outputs\\CodeGemma_zero-shot.py\", line 20, in test_unsorted_array\n    self.assertEqual(max_chain_length(pairs, 3), 3)\nAssertionError: 2 != 3\n\n----------------------------------------------------------------------\nRan 4 tests in 0.001s\n\nFAILED (failures=2)\n",
        "test_smells": {
          "redundant_assertion": 2,
          "magic_number": 10
        }
      },
      "few-shot": {
        "status": "failed",
        "coverage": "-",
        "assert_types": [
          "assertEqual"
        ],
        "edge_case_found": true,
        "functions_tested": 1,
        "total_functions": 2,
        "score": 0.1,
        "stdout": "",
        "stderr": ".F...\n======================================================================\nFAIL: test_large_array (__main__.TestMaxChainLength.test_large_array)\n----------------------------------------------------------------------\nTraceback (most recent call last):\n  File \"C:\\Users\\antho\\OneDrive\\Área de Trabalho\\testPilotAI\\test_outputs\\CodeGemma_few-shot.py\", line 23, in test_large_array\n    self.assertEqual(max_chain_length(arr, 1000), 1000)\nAssertionError: 500 != 1000\n\n----------------------------------------------------------------------\nRan 5 tests in 0.144s\n\nFAILED (failures=1)\n",
        "test_smells": {
          "redundant_assertion": 2,
          "magic_number": 17
        }
      },
      "cot": {
        "status": "failed",
        "coverage": "-",
        "assert_types": [
          "assertEqual"
        ],
        "edge_case_found": true,
        "functions_tested": 1,
        "total_functions": 2,
        "score": 0.1,
        "stdout": "",
        "stderr": "F.F.FF\n======================================================================\nFAIL: test_duplicates (__main__.TestMaxChainLength.test_duplicates)\n----------------------------------------------------------------------\nTraceback (most recent call last):\n  File \"C:\\Users\\antho\\OneDrive\\Área de Trabalho\\testPilotAI\\test_outputs\\CodeGemma_cot.py\", line 30, in test_duplicates\n    self.assertEqual(max_chain_length(arr, n), 3)\nAssertionError: 1 != 3\n\n======================================================================\nFAIL: test_large_array (__main__.TestMaxChainLength.test_large_array)\n----------------------------------------------------------------------\nTraceback (most recent call last):\n  File \"C:\\Users\\antho\\OneDrive\\Área de Trabalho\\testPilotAI\\test_outputs\\CodeGemma_cot.py\", line 35, in test_large_array\n    self.assertEqual(max_chain_length(arr, n), 1000)\nAssertionError: 500 != 1000\n\n======================================================================\nFAIL: test_sorted_array (__main__.TestMaxChainLength.test_sorted_array)\n----------------------------------------------------------------------\nTraceback (most recent call last):\n  File \"C:\\Users\\antho\\OneDrive\\Área de Trabalho\\testPilotAI\\test_outputs\\CodeGemma_cot.py\", line 20, in test_sorted_array\n    self.assertEqual(max_chain_length(arr, n), 3)\nAssertionError: 2 != 3\n\n======================================================================\nFAIL: test_unsorted_array (__main__.TestMaxChainLength.test_unsorted_array)\n----------------------------------------------------------------------\nTraceback (most recent call last):\n  File \"C:\\Users\\antho\\OneDrive\\Área de Trabalho\\testPilotAI\\test_outputs\\CodeGemma_cot.py\", line 25, in test_unsorted_array\n    self.assertEqual(max_chain_length(arr, n), 3)\nAssertionError: 2 != 3\n\n----------------------------------------------------------------------\nRan 6 tests in 0.138s\n\nFAILED (failures=4)\n",
        "test_smells": {
          "redundant_assertion": 2,
          "magic_number": 21
        }
      }
    }
  }